<?xml version="1.0" encoding="utf-8"?>
<!-- This URDF was automatically created by SolidWorks to URDF Exporter! Originally created by Stephen Brawner (brawner@gmail.com) 
     Commit Version: 1.6.0-4-g7f85cfe  Build Version: 1.6.7995.38578
     For more information, please see http://wiki.ros.org/sw_urdf_exporter -->
<robot
  name="wsybot_v.3">
  <link
    name="base_link">
    <inertial>
      <origin
        xyz="-0.067351 -1.948E-05 -0.010105"
        rpy="0 0 0" />
      <mass
        value="3.5223" />
      <inertia
        ixx="0.019363"
        ixy="2.879E-05"
        ixz="0.0023599"
        iyy="0.019162"
        iyz="5.64E-06"
        izz="0.034264" />
    </inertial>
    <visual>
      <origin
        xyz="0 0 0"
        rpy="0 0 0" />
      <geometry>
        <mesh
          filename="../meshes/base_link.STL" />
      </geometry>
      <material
        name="">
        <color
          rgba="0 0 0 1" />
      </material>
    </visual>
    <collision>
      <origin
        xyz="0 0 0"
        rpy="0 0 0" />
      <geometry>
        <box size="0.8 0.8 0.3" />
      </geometry>
    </collision>
  </link>
  <link
    name="left_leg_roll_link">
    <inertial>
      <origin
        xyz="0.041063 0.037875 -0.068969"
        rpy="0 0 0" />
      <mass
        value="1.7817" />
      <inertia
        ixx="0.012874"
        ixy="0.0031336"
        ixz="-0.0056433"
        iyy="0.014074"
        iyz="-0.0050334"
        izz="0.0072867" />
    </inertial>
    <visual>
      <origin
        xyz="0 0 0"
        rpy="0 0 0" />
      <geometry>
        <mesh
          filename="../meshes/left_leg_roll_link.STL" />
      </geometry>
      <material
        name="">
        <color
          rgba="0 0 0 1" />
      </material>
    </visual>
    <!-- <collision>
      <origin
        xyz="0 0 0"
        rpy="0 0 0" />
      <geometry>
        <mesh
          filename="package://wsybot_v.3/meshes/left_leg_roll_link.STL" />
      </geometry>
    </collision> -->
  </link>
  <joint
    name="left_leg_roll_joint"
    type="revolute">
    <origin
      xyz="-0.027 0.07 -0.01"
      rpy="0 0 0" />
    <parent
      link="base_link" />
    <child
      link="left_leg_roll_link" />
    <axis
      xyz="1 0 0" />
    <limit
      lower="-0.15"
      upper="0.7"
      effort="120"
      velocity="10.472" />
    <dynamics
      damping="0"
      friction="0" />
  </joint>
  <link
    name="left_leg_pitch_link">
    <inertial>
      <origin
        xyz="0.013423 0.031248 -0.076126"
        rpy="0 0 0" />
      <mass
        value="0.71642" />
      <inertia
        ixx="0.0062349"
        ixy="0.00034223"
        ixz="-0.00091218"
        iyy="0.005599"
        iyz="-0.0019409"
        izz="0.0012225" />
    </inertial>
    <visual>
      <origin
        xyz="0 0 0"
        rpy="0 0 0" />
      <geometry>
        <mesh
          filename="../meshes/left_leg_pitch_link.STL" />
      </geometry>
      <material
        name="">
        <color
          rgba="0 0 0 1" />
      </material>
    </visual>
    <!-- <collision>
      <origin
        xyz="0 0 0"
        rpy="0 0 0" />
      <geometry>
        <mesh
          filename="package://wsybot_v.3/meshes/left_leg_pitch_link.STL" />
      </geometry>
    </collision> -->
  </link>
  <joint
    name="left_leg_pitch_joint"
    type="revolute">
    <origin
      xyz="0.047 -0.0025 -0.075"
      rpy="0 0 0" />
    <parent
      link="left_leg_roll_link" />
    <child
      link="left_leg_pitch_link" />
    <axis
      xyz="0 -1 0" />
    <limit
      lower="-1"
      upper="1.2"
      effort="120"
      velocity="10.472" />
    <dynamics
      damping="0"
      friction="0" />
  </joint>
  <link
    name="left_leg_yaw_link">
    <inertial>
      <origin
        xyz="0.02393 -0.031356 -0.13509"
        rpy="0 0 0" />
      <mass
        value="1.7952" />
      <inertia
        ixx="0.03895"
        ixy="-0.0013431"
        ixz="-0.0064161"
        iyy="0.038696"
        iyz="0.0075837"
        izz="0.0038731" />
    </inertial>
    <visual>
      <origin
        xyz="0 0 0"
        rpy="0 0 0" />
      <geometry>
        <mesh
          filename="../meshes/left_leg_yaw_link.STL" />
      </geometry>
      <material
        name="">
        <color
          rgba="0 0 0 1" />
      </material>
    </visual>
    <!-- <collision>
      <origin
        xyz="0 0 0"
        rpy="0 0 0" />
      <geometry>
        <mesh
          filename="package://wsybot_v.3/meshes/left_leg_yaw_link.STL" />
      </geometry>
    </collision> -->
  </link>
  <joint
    name="left_leg_yaw_joint"
    type="revolute">
    <origin
      xyz="0.0254394580282023 0.043500000000003 -0.144274335816291"
      rpy="0 0 0" />
    <parent
      link="left_leg_pitch_link" />
    <child
      link="left_leg_yaw_link" />
    <axis
      xyz="0.173648177666925 0 -0.984807753012209" />
    <limit
      lower="-1"
      upper="1"
      effort="27"
      velocity="5.5" />
    <dynamics
      damping="0"
      friction="0" />
  </joint>
  <link
    name="left_knee_link">
    <inertial>
      <origin
        xyz="-0.054417 0.0083359 -0.20323"
        rpy="0 0 0" />
      <mass
        value="0.82452" />
      <inertia
        ixx="0.044487"
        ixy="-0.0006678"
        ixz="0.011781"
        iyy="0.047508"
        iyz="-0.0024963"
        izz="0.0036395" />
    </inertial>
    <visual>
      <origin
        xyz="0 0 0"
        rpy="0 0 0" />
      <geometry>
        <mesh
          filename="../meshes/left_knee_link.STL" />
      </geometry>
      <material
        name="">
        <color
          rgba="0 0 0 1" />
      </material>
    </visual>
    <collision>
      <origin
        xyz="0 -0.015 0"
        rpy="0 0 0" />
      <geometry>
        <cylinder length="0.3" radius="0.08" />
      </geometry>
    </collision>
  </link>
  <joint
    name="left_knee_joint"
    type="revolute">
    <origin
      xyz="0.0266549952718271 0.00670000000034304 -0.151167990087403"
      rpy="0 0 0" />
    <parent
      link="left_leg_yaw_link" />
    <child
      link="left_knee_link" />
    <axis
      xyz="0 1 0" />
    <limit
      lower="-0.4"
      upper="1.5"
      effort="120"
      velocity="10.472" />
    <dynamics
      damping="0"
      friction="0" />
  </joint>
  <link
    name="left_ankle_pitch_link">
    <inertial>
      <origin
        xyz="0.023429 -0.0364 -0.0437"
        rpy="0 0 0" />
      <mass
        value="0.51357" />
      <inertia
        ixx="0.0019465"
        ixy="-0.00048604"
        ixz="-0.00060294"
        iyy="0.0015855"
        iyz="0.00089759"
        izz="0.0012065" />
    </inertial>
    <visual>
      <origin
        xyz="0 0 0"
        rpy="0 0 0" />
      <geometry>
        <mesh
          filename="../meshes/left_ankle_pitch_link.STL" />
      </geometry>
      <material
        name="">
        <color
          rgba="0 0 0 1" />
      </material>
    </visual>
    <!-- <collision>
      <origin
        xyz="0 0 0"
        rpy="0 0 0" />
      <geometry>
        <mesh
          filename="package://wsybot_v.3/meshes/left_ankle_pitch_link.STL" />
      </geometry>
    </collision> -->
  </link>
  <joint
    name="left_ankle_pitch_joint"
    type="revolute">
    <origin
      xyz="-0.0776457135307382 -0.00575000000036324 -0.289777747886718"
      rpy="0 0 0" />
    <parent
      link="left_knee_link" />
    <child
      link="left_ankle_pitch_link" />
    <axis
      xyz="0 -1 0" />
    <limit
      lower="-1"
      upper="1"
      effort="27"
      velocity="5.5" />
    <dynamics
      damping="0"
      friction="0" />
  </joint>
  <link
    name="left_ankle_roll_link">
    <inertial>
      <origin
        xyz="0.022431 0 -0.035744"
        rpy="0 0 0" />
      <mass
        value="0.55727" />
      <inertia
        ixx="0.0010521"
        ixy="4E-08"
        ixz="-0.00058088"
        iyy="0.0031812"
        iyz="-2E-08"
        izz="0.0025829" />
    </inertial>
    <visual>
      <origin
        xyz="0 0 0"
        rpy="0 0 0" />
      <geometry>
        <mesh
          filename="../meshes/left_ankle_roll_link.STL" />
      </geometry>
      <material
        name="">
        <color
          rgba="0 0 0 1" />
      </material>
    </visual>
    <collision>
      <origin
        xyz="0 0 0"
        rpy="0 0 0" />
      <geometry>
        <mesh
          filename="../meshes/left_ankle_roll_link.STL" />
      </geometry>
    </collision>
  </link>
  <joint
    name="left_ankle_roll_joint"
    type="revolute">
    <origin
      xyz="0.000250000000259765 -0.0402500000000252 -0.049999999999963"
      rpy="0 0 0" />
    <parent
      link="left_ankle_pitch_link" />
    <child
      link="left_ankle_roll_link" />
    <axis
      xyz="-1 0 0" />
    <limit
      lower="-0.5"
      upper="0.5"
      effort="27"
      velocity="5.5" />
    <dynamics
      damping="0"
      friction="0" />
  </joint>
  <link
    name="right_leg_roll_link">
    <inertial>
      <origin
        xyz="0.041283 -0.037875 -0.068969"
        rpy="0 0 0" />
      <mass
        value="1.7817" />
      <inertia
        ixx="0.012874"
        ixy="-0.0031507"
        ixz="-0.0056739"
        iyy="0.014111"
        iyz="0.0050334"
        izz="0.0073234" />
    </inertial>
    <visual>
      <origin
        xyz="0 0 0"
        rpy="0 0 0" />
      <geometry>
        <mesh
          filename="../meshes/right_leg_roll_link.STL" />
      </geometry>
      <material
        name="">
        <color
          rgba="0 0 0 1" />
      </material>
    </visual>
    <!-- <collision>
      <origin
        xyz="0 0 0"
        rpy="0 0 0" />
      <geometry>
        <mesh
          filename="package://wsybot_v.3/meshes/right_leg_roll_link.STL" />
      </geometry>
    </collision> -->
  </link>
  <joint
    name="right_leg_roll_joint"
    type="revolute">
    <origin
      xyz="-0.027 -0.07 -0.01"
      rpy="0 0 0" />
    <parent
      link="base_link" />
    <child
      link="right_leg_roll_link" />
    <axis
      xyz="1 0 0" />
    <limit
      lower="-0.7"
      upper="0.15"
      effort="120"
      velocity="10.472" />
    <dynamics
      damping="0"
      friction="0" />
  </joint>
  <link
    name="right_leg_pitch_link">
    <inertial>
      <origin
        xyz="0.013423 -0.031248 -0.076126"
        rpy="0 0 0" />
      <mass
        value="0.71642" />
      <inertia
        ixx="0.0062349"
        ixy="-0.00034223"
        ixz="-0.00091217"
        iyy="0.005599"
        iyz="0.0019409"
        izz="0.0012225" />
    </inertial>
    <visual>
      <origin
        xyz="0 0 0"
        rpy="0 0 0" />
      <geometry>
        <mesh
          filename="../meshes/right_leg_pitch_link.STL" />
      </geometry>
      <material
        name="">
        <color
          rgba="0 0 0 1" />
      </material>
    </visual>
    <!-- <collision>
      <origin
        xyz="0 0 0"
        rpy="0 0 0" />
      <geometry>
        <mesh
          filename="package://wsybot_v.3/meshes/right_leg_pitch_link.STL" />
      </geometry>
    </collision> -->
  </link>
  <joint
    name="right_leg_pitch_joint"
    type="revolute">
    <origin
      xyz="0.0469999999999982 0.00250000000000683 -0.0749999867630524"
      rpy="0 0 0" />
    <parent
      link="right_leg_roll_link" />
    <child
      link="right_leg_pitch_link" />
    <axis
      xyz="0 1 0" />
    <limit
      lower="-1.2"
      upper="1"
      effort="120"
      velocity="10.472" />
    <dynamics
      damping="0"
      friction="0" />
  </joint>
  <link
    name="right_leg_yaw_link">
    <inertial>
      <origin
        xyz="0.023716 0.031356 -0.13513"
        rpy="0 0 0" />
      <mass
        value="1.7952" />
      <inertia
        ixx="0.038971"
        ixy="0.0013317"
        ixz="-0.0063586"
        iyy="0.038696"
        iyz="-0.0075857"
        izz="0.0038522" />
    </inertial>
    <visual>
      <origin
        xyz="0 0 0"
        rpy="0 0 0" />
      <geometry>
        <mesh
          filename="../meshes/right_leg_yaw_link.STL" />
      </geometry>
      <material
        name="">
        <color
          rgba="0 0 0 1" />
      </material>
    </visual>
    <!-- <collision>
      <origin
        xyz="0 0 0"
        rpy="0 0 0" />
      <geometry>
        <mesh
          filename="package://wsybot_v.3/meshes/right_leg_yaw_link.STL" />
      </geometry>
    </collision> -->
  </link>
  <joint
    name="right_leg_yaw_joint"
    type="revolute">
    <origin
      xyz="0.0254394580282356 -0.0434999999999856 -0.144274335816282"
      rpy="0 0 0" />
    <parent
      link="right_leg_pitch_link" />
    <child
      link="right_leg_yaw_link" />
    <axis
      xyz="0.173648177666924 0 -0.984807753012209" />
    <limit
      lower="-1"
      upper="1"
      effort="27"
      velocity="5.5" />
    <dynamics
      damping="0"
      friction="0" />
  </joint>
  <link
    name="right_knee_link">
    <inertial>
      <origin
        xyz="-0.054417 -0.0083359 -0.20323"
        rpy="0 0 0" />
      <mass
        value="0.82452" />
      <inertia
        ixx="0.044487"
        ixy="0.0006678"
        ixz="0.011781"
        iyy="0.047508"
        iyz="0.0024963"
        izz="0.0036395" />
    </inertial>
    <visual>
      <origin
        xyz="0 0 0"
        rpy="0 0 0" />
      <geometry>
        <mesh
          filename="../meshes/right_knee_link.STL" />
      </geometry>
      <material
        name="">
        <color
          rgba="0 0 0 1" />
      </material>
    </visual>
    <collision>
      <origin
        xyz="0 0.015 0"
        rpy="0 0 0" />
      <geometry>
        <cylinder length="0.3" radius="0.08" />
      </geometry>
    </collision>
  </link>
  <joint
    name="right_knee_joint"
    type="revolute">
    <origin
      xyz="0.026654995271894 -0.00670000000000134 -0.151167990087366"
      rpy="0 0 0" />
    <parent
      link="right_leg_yaw_link" />
    <child
      link="right_knee_link" />
    <axis
      xyz="0 -1 0" />
    <limit
      lower="-1.5"
      upper="0.4"
      effort="120"
      velocity="10.472" />
    <dynamics
      damping="0"
      friction="0" />
  </joint>
  <link
    name="right_ankle_pitch_link">
    <inertial>
      <origin
        xyz="0.023429 0.0364 -0.0437"
        rpy="0 0 0" />
      <mass
        value="0.51357" />
      <inertia
        ixx="0.0019465"
        ixy="0.00048604"
        ixz="-0.00060294"
        iyy="0.0015855"
        iyz="-0.00089758"
        izz="0.0012065" />
    </inertial>
    <visual>
      <origin
        xyz="0 0 0"
        rpy="0 0 0" />
      <geometry>
        <mesh
          filename="../meshes/right_ankle_pitch_link.STL" />
      </geometry>
      <material
        name="">
        <color
          rgba="0 0 0 1" />
      </material>
    </visual>
    <!-- <collision>
      <origin
        xyz="0 0 0"
        rpy="0 0 0" />
      <geometry>
        <mesh
          filename="package://wsybot_v.3/meshes/right_ankle_pitch_link.STL" />
      </geometry>
    </collision> -->
  </link>
  <joint
    name="right_ankle_pitch_joint"
    type="revolute">
    <origin
      xyz="-0.0776457135307703 0.0057500000000052 -0.289777747886716"
      rpy="0 0 0" />
    <parent
      link="right_knee_link" />
    <child
      link="right_ankle_pitch_link" />
    <axis
      xyz="0 1 0" />
    <limit
      lower="-1"
      upper="1"
      effort="27"
      velocity="5.5" />
    <dynamics
      damping="0"
      friction="0" />
  </joint>
  <link
    name="right_ankle_roll_link">
    <inertial>
      <origin
        xyz="0.022431 0 -0.035744"
        rpy="0 0 0" />
      <mass
        value="0.55727" />
      <inertia
        ixx="0.0010521"
        ixy="4E-08"
        ixz="-0.00058088"
        iyy="0.0031812"
        iyz="-2E-08"
        izz="0.0025829" />
    </inertial>
    <visual>
      <origin
        xyz="0 0 0"
        rpy="0 0 0" />
      <geometry>
        <mesh
          filename="../meshes/right_ankle_roll_link.STL" />
      </geometry>
      <material
        name="">
        <color
          rgba="0 0 0 1" />
      </material>
    </visual>
    <collision>
      <origin
        xyz="0 0 0"
        rpy="0 0 0" />
      <geometry>
        <mesh
          filename="../meshes/right_ankle_roll_link.STL" />
      </geometry>
    </collision>
  </link>
  <joint
    name="right_ankle_roll_joint"
    type="revolute">
    <origin
      xyz="0.000249999999972779 0.040249999999599 -0.0499999999999262"
      rpy="0 0 0" />
    <parent
      link="right_ankle_pitch_link" />
    <child
      link="right_ankle_roll_link" />
    <axis
      xyz="-1 0 0" />
    <limit
      lower="-0.5"
      upper="0.5"
      effort="27"
      velocity="5.5" />
    <dynamics
      damping="0"
      friction="0" />
  </joint>
</robot>